Workbook

Sheet Data Export
A1: Participant Key | B1: Group | C1: Task_1_G1 | D1: Task_1_G2 | E1: Task_1_G3 | F1: Task_1_G4 | G1: Task_1_G5 | H1: Task_1_G6 | I1: Task_1_G7 | J1: Task_1_G8 | K1: Task_1_G9 | L1: Task_1_G10 | M1: Task_1_G11 | N1: Task_1_G12 | O1: Task_1_G13 | P1: Task_1_G14 | Q1: Task_2 | R1: Task_3 | S1: Task_1_P_Unscaled | T1: Task_1_P_Scaled | U1: Task_1_Perf | V1: Task_1_p | W1: Task_1_A1 | X1: Task_1_A2 | Y1: Task_1_A3 | Z1: Task_1_A4 | AA1: Task_1_A5 | AB1: Task_1_A6 | AC1: Task_1_A7 | AD1: Task_1_A8 | AE1: Task_1_A9 | AF1: Task_1_A10 | AG1: Task_1_A11 | AH1: Task_1_A12 | AI1: Task_1_A13 | AJ1: Task_1_A14 | AK1: Task_2_A | AL1: Task_3_A | AM1: Task_1_M1 | AN1: Task_1_M2 | AO1: Task_1_M3 | AP1: Task_1_M4 | AQ1: Task_1_M5 | AR1: Task_1_M6 | AS1: Task_1_M7 | AT1: Task_1_M8 | AU1: Task_1_M9 | AV1: Task_1_M10 | AW1: Task_1_M11 | AX1: Task_1_M12 | AY1: Task_1_M13 | AZ1: Task_1_M14 | BA1: Task_2_M | BB1: Task_3_M | BC1: Max_Unscaled | BD1: Max_Scaled
A2: ='Task 1'!A48 -> fe6c | B2: =VLOOKUP(A2,'Task 1'!A$48:B$59,2,FALSE) -> B | C2: =VLOOKUP($A2,'Task 1'!$A$16:$P$27,'Task 1'!C$14,FALSE) -> 3 | D2: =VLOOKUP($A2,'Task 1'!$A$16:$P$27,'Task 1'!D$14,FALSE) -> 1 | E2: =VLOOKUP($A2,'Task 1'!$A$16:$P$27,'Task 1'!E$14,FALSE) -> 1 | F2: =VLOOKUP($A2,'Task 1'!$A$16:$P$27,'Task 1'!F$14,FALSE) -> 1 | G2: =VLOOKUP($A2,'Task 1'!$A$16:$P$27,'Task 1'!G$14,FALSE) -> 0 | H2: =VLOOKUP($A2,'Task 1'!$A$16:$P$27,'Task 1'!H$14,FALSE) -> 1 | I2: =VLOOKUP($A2,'Task 1'!$A$16:$P$27,'Task 1'!I$14,FALSE) -> 1 | J2: =VLOOKUP($A2,'Task 1'!$A$16:$P$27,'Task 1'!J$14,FALSE) -> 1 | ... P2: =VLOOKUP($A2,'Task 1'!$A$16:$P$27,'Task 1'!P$14,FALSE) -> 0 | Q2: =VLOOKUP($A2,'Task 2'!$A$2:$J$12,10,FALSE) -> 0 | R2: =VLOOKUP($A2,'Task 3'!$A$2:$J$12,10,FALSE) -> 0 | S2: =VLOOKUP($A2,'Task 1'!$A$16:$V$27,17,FALSE) -> 13 | T2: =VLOOKUP($A2,'Task 1'!$A$16:$V$27,18,FALSE) -> 51 | U2: =VLOOKUP($A2,'Task 1'!$A$16:$V$27,19,FALSE) -> 0.60714286 | V2: =VLOOKUP($A2,'Task 1'!$A$16:$W$27,23,FALSE) -> 0.58333333 | W2: =IF(VLOOKUP($A2,'Task 1'!$A$2:$P$13,'Task 1'!C$14,FALSE)="","",VLOOKUP($A2,'Task 1'!$A$2:$P$13,'Task 1'!C$14,FALSE)) -> The goal is to enhance the `finance_tracker` project by adding income tracking functionality to complement the existing expense, budget, user, and reporting features. | X2: =IF(VLOOKUP($A2,'Task 1'!$A$2:$P$13,'Task 1'!D$14,FALSE)="","",VLOOKUP($A2,'Task 1'!$A$2:$P$13,'Task 1'!D$14,FALSE)) -> No, the task was not completed. | Y2: =IF(VLOOKUP($A2,'Task 1'!$A$2:$P$13,'Task 1'!E$14,FALSE)="","",VLOOKUP($A2,'Task 1'!$A$2:$P$13,'Task 1'!E$14,FALSE)) -> Gather relevant information', 'summarize requirements', 'code implementation and show the diff', 'run tests and solve runtime errors' | Z2: =IF(VLOOKUP($A2,'Task 1'!$A$2:$P$13,'Task 1'!F$14,FALSE)="","",VLOOKUP($A2,'Task 1'!$A$2:$P$13,'Task 1'!F$14,FALSE)) -> run tests and modify the code to solve errors. | AA2: =IF(VLOOKUP($A2,'Task 1'!$A$2:$P$13,'Task 1'!G$14,FALSE)="","",VLOOKUP($A2,'Task 1'!$A$2:$P$13,'Task 1'!G$14,FALSE)) | AB2: =IF(VLOOKUP($A2,'Task 1'!$A$2:$P$13,'Task 1'!H$14,FALSE)="","",VLOOKUP($A2,'Task 1'!$A$2:$P$13,'Task 1'!H$14,FALSE)) -> Yes, maybe the step where it try to solve the same runtime errors again and again. | AC2: =IF(VLOOKUP($A2,'Task 1'!$A$2:$P$13,'Task 1'!I$14,FALSE)="","",VLOOKUP($A2,'Task 1'!$A$2:$P$13,'Task 1'!I$14,FALSE)) -> --old_str 'from finance_tracker.reports import FinancialReport' --new_str 'from finance_tracker.reports import FinancialReport from finance_tracker.income import IncomeTracker' | AD2: =IF(VLOOKUP($A2,'Task 1'!$A$2:$P$13,'Task 1'!J$14,FALSE)="","",VLOOKUP($A2,'Task 1'!$A$2:$P$13,'Task 1'!J$14,FALSE)) -> finance_tracker/cli.py, finance_tracker/reports.py | ... AJ2: =IF(VLOOKUP($A2,'Task 1'!$A$2:$P$13,'Task 1'!P$14,FALSE)="","",VLOOKUP($A2,'Task 1'!$A$2:$P$13,'Task 1'!P$14,FALSE)) | AK2: =IF(VLOOKUP($A2,Form_Responses8[[Participant Key]:[Find and describe all potential bugs!]],3,FALSE)="","",VLOOKUP($A2,Form_Responses8[[Participant Key]:[Find and describe all potential bugs!]],3,FALSE)) -> Agent's logic: failed to change to another method to fix the issue. Implementation: the line break conditional statements seems was incorrect at some point. | AL2: =IF(VLOOKUP($A2,Form_Responses6[[Participant Key]:[Find and describe all potential bugs!]],3,FALSE)="","",VLOOKUP($A2,Form_Responses6[[Participant Key]:[Find and describe all potential bugs!]],3,FALSE)) -> Agent's decision making: the failed command outputs mention that more commands could be run in a docker container, but the agent fails to adjust the next steps to adapt it. Logic: allows the failed steps repeat multiple times. | AM2: {=INDEX('Task 1'!$B$30:$B$43,COLUMN(A1))} -> 3 | AN2: {=INDEX('Task 1'!$B$30:$B$43,COLUMN(B1))} -> 1 | AO2: {=INDEX('Task 1'!$B$30:$B$43,COLUMN(C1))} -> 2 | AP2: {=INDEX('Task 1'!$B$30:$B$43,COLUMN(D1))} -> 1 | AQ2: {=INDEX('Task 1'!$B$30:$B$43,COLUMN(E1))} -> 1 | AR2: {=INDEX('Task 1'!$B$30:$B$43,COLUMN(F1))} -> 2 | AS2: {=INDEX('Task 1'!$B$30:$B$43,COLUMN(G1))} -> 1 | AT2: {=INDEX('Task 1'!$B$30:$B$43,COLUMN(H1))} -> 2 | ... AZ2: {=INDEX('Task 1'!$B$30:$B$43,COLUMN(N1))} -> 2 | BA2: 1 | BB2: 1 | BC2: ='Task 1'!$B$45 -> 21 | BD2: ='Task 1'!$D$45 -> 84
A3: ='Task 1'!A49 -> 67c3 | B3: =VLOOKUP(A3,'Task 1'!A$48:B$59,2,FALSE) -> B | C3: =VLOOKUP($A3,'Task 1'!$A$16:$P$27,'Task 1'!C$14,FALSE) -> 0 | D3: =VLOOKUP($A3,'Task 1'!$A$16:$P$27,'Task 1'!D$14,FALSE) -> 1 | E3: =VLOOKUP($A3,'Task 1'!$A$16:$P$27,'Task 1'!E$14,FALSE) -> 0 | F3: =VLOOKUP($A3,'Task 1'!$A$16:$P$27,'Task 1'!F$14,FALSE) -> 0 | G3: =VLOOKUP($A3,'Task 1'!$A$16:$P$27,'Task 1'!G$14,FALSE) -> 0 | H3: =VLOOKUP($A3,'Task 1'!$A$16:$P$27,'Task 1'!H$14,FALSE) -> 0 | I3: =VLOOKUP($A3,'Task 1'!$A$16:$P$27,'Task 1'!I$14,FALSE) -> 0 | J3: =VLOOKUP($A3,'Task 1'!$A$16:$P$27,'Task 1'!J$14,FALSE) -> 0 | ... P3: =VLOOKUP($A3,'Task 1'!$A$16:$P$27,'Task 1'!P$14,FALSE) -> 0 | Q3: =VLOOKUP($A3,'Task 2'!$A$2:$J$12,10,FALSE) -> 0 | R3: =VLOOKUP($A3,'Task 3'!$A$2:$J$12,10,FALSE) -> 0 | S3: =VLOOKUP($A3,'Task 1'!$A$16:$V$27,17,FALSE) -> 2 | T3: =VLOOKUP($A3,'Task 1'!$A$16:$V$27,18,FALSE) -> 12 | U3: =VLOOKUP($A3,'Task 1'!$A$16:$V$27,19,FALSE) -> 0.14285714 | V3: =VLOOKUP($A3,'Task 1'!$A$16:$W$27,23,FALSE) -> 0.91666667 | W3: =IF(VLOOKUP($A3,'Task 1'!$A$2:$P$13,'Task 1'!C$14,FALSE)="","",VLOOKUP($A3,'Task 1'!$A$2:$P$13,'Task 1'!C$14,FALSE)) | X3: =IF(VLOOKUP($A3,'Task 1'!$A$2:$P$13,'Task 1'!D$14,FALSE)="","",VLOOKUP($A3,'Task 1'!$A$2:$P$13,'Task 1'!D$14,FALSE)) -> No, the task was not completed. | Y3: =IF(VLOOKUP($A3,'Task 1'!$A$2:$P$13,'Task 1'!E$14,FALSE)="","",VLOOKUP($A3,'Task 1'!$A$2:$P$13,'Task 1'!E$14,FALSE)) -> Execute solutions and take over corrections | Z3: =IF(VLOOKUP($A3,'Task 1'!$A$2:$P$13,'Task 1'!F$14,FALSE)="","",VLOOKUP($A3,'Task 1'!$A$2:$P$13,'Task 1'!F$14,FALSE)) -> Ask and add error fixes | AA3: =IF(VLOOKUP($A3,'Task 1'!$A$2:$P$13,'Task 1'!G$14,FALSE)="","",VLOOKUP($A3,'Task 1'!$A$2:$P$13,'Task 1'!G$14,FALSE)) -> Missing libraries, non-working feature | AB3: =IF(VLOOKUP($A3,'Task 1'!$A$2:$P$13,'Task 1'!H$14,FALSE)="","",VLOOKUP($A3,'Task 1'!$A$2:$P$13,'Task 1'!H$14,FALSE)) | AC3: =IF(VLOOKUP($A3,'Task 1'!$A$2:$P$13,'Task 1'!I$14,FALSE)="","",VLOOKUP($A3,'Task 1'!$A$2:$P$13,'Task 1'!I$14,FALSE)) | AD3: =IF(VLOOKUP($A3,'Task 1'!$A$2:$P$13,'Task 1'!J$14,FALSE)="","",VLOOKUP($A3,'Task 1'!$A$2:$P$13,'Task 1'!J$14,FALSE)) | ... AJ3: =IF(VLOOKUP($A3,'Task 1'!$A$2:$P$13,'Task 1'!P$14,FALSE)="","",VLOOKUP($A3,'Task 1'!$A$2:$P$13,'Task 1'!P$14,FALSE)) | AK3: =IF(VLOOKUP($A3,Form_Responses8[[Participant Key]:[Find and describe all potential bugs!]],3,FALSE)="","",VLOOKUP($A3,Form_Responses8[[Participant Key]:[Find and describe all potential bugs!]],3,FALSE)) | AL3: =IF(VLOOKUP($A3,Form_Responses6[[Participant Key]:[Find and describe all potential bugs!]],3,FALSE)="","",VLOOKUP($A3,Form_Responses6[[Participant Key]:[Find and describe all potential bugs!]],3,FALSE)) -> No access to the environment and therefore can’t install or update anything, missing tools that are supposed to be used | AM3: {=INDEX('Task 1'!$B$30:$B$43,COLUMN(A2))} -> 3 | AN3: {=INDEX('Task 1'!$B$30:$B$43,COLUMN(B2))} -> 1 | AO3: {=INDEX('Task 1'!$B$30:$B$43,COLUMN(C2))} -> 2 | AP3: {=INDEX('Task 1'!$B$30:$B$43,COLUMN(D2))} -> 1 | AQ3: {=INDEX('Task 1'!$B$30:$B$43,COLUMN(E2))} -> 1 | AR3: {=INDEX('Task 1'!$B$30:$B$43,COLUMN(F2))} -> 2 | AS3: {=INDEX('Task 1'!$B$30:$B$43,COLUMN(G2))} -> 1 | AT3: {=INDEX('Task 1'!$B$30:$B$43,COLUMN(H2))} -> 2 | ... AZ3: {=INDEX('Task 1'!$B$30:$B$43,COLUMN(N2))} -> 2 | BA3: 1 | BB3: 1 | BC3: ='Task 1'!$B$45 -> 21 | BD3: ='Task 1'!$D$45 -> 84
A4: ='Task 1'!A50 -> 0078 | B4: =VLOOKUP(A4,'Task 1'!A$48:B$59,2,FALSE) -> A | C4: =VLOOKUP($A4,'Task 1'!$A$16:$P$27,'Task 1'!C$14,FALSE) -> 2 | D4: =VLOOKUP($A4,'Task 1'!$A$16:$P$27,'Task 1'!D$14,FALSE) -> 0 | E4: =VLOOKUP($A4,'Task 1'!$A$16:$P$27,'Task 1'!E$14,FALSE) -> 0 | F4: =VLOOKUP($A4,'Task 1'!$A$16:$P$27,'Task 1'!F$14,FALSE) -> 1 | G4: =VLOOKUP($A4,'Task 1'!$A$16:$P$27,'Task 1'!G$14,FALSE) -> 1 | H4: =VLOOKUP($A4,'Task 1'!$A$16:$P$27,'Task 1'!H$14,FALSE) -> 1 | I4: =VLOOKUP($A4,'Task 1'!$A$16:$P$27,'Task 1'!I$14,FALSE) -> 1 | J4: =VLOOKUP($A4,'Task 1'!$A$16:$P$27,'Task 1'!J$14,FALSE) -> 2 | ... P4: =VLOOKUP($A4,'Task 1'!$A$16:$P$27,'Task 1'!P$14,FALSE) -> 0 | Q4: =VLOOKUP($A4,'Task 2'!$A$2:$J$12,10,FALSE) -> 0 | R4: =VLOOKUP($A4,'Task 3'!$A$2:$J$12,10,FALSE) -> 1 | S4: =VLOOKUP($A4,'Task 1'!$A$16:$V$27,17,FALSE) -> 13 | T4: =VLOOKUP($A4,'Task 1'!$A$16:$V$27,18,FALSE) -> 55 | U4: =VLOOKUP($A4,'Task 1'!$A$16:$V$27,19,FALSE) -> 0.6547619 | V4: =VLOOKUP($A4,'Task 1'!$A$16:$W$27,23,FALSE) -> 0.5 | W4: =IF(VLOOKUP($A4,'Task 1'!$A$2:$P$13,'Task 1'!C$14,FALSE)="","",VLOOKUP($A4,'Task 1'!$A$2:$P$13,'Task 1'!C$14,FALSE)) -> The agents goal is to implement an income tracking feature to a python project with cli functionality and integrating it into the rest of the program. | X4: =IF(VLOOKUP($A4,'Task 1'!$A$2:$P$13,'Task 1'!D$14,FALSE)="","",VLOOKUP($A4,'Task 1'!$A$2:$P$13,'Task 1'!D$14,FALSE)) -> Yes, the task was completed successfully. | Y4: =IF(VLOOKUP($A4,'Task 1'!$A$2:$P$13,'Task 1'!E$14,FALSE)="","",VLOOKUP($A4,'Task 1'!$A$2:$P$13,'Task 1'!E$14,FALSE)) -> Adding functionality of income tracking and integrating it into the CLI | Z4: =IF(VLOOKUP($A4,'Task 1'!$A$2:$P$13,'Task 1'!F$14,FALSE)="","",VLOOKUP($A4,'Task 1'!$A$2:$P$13,'Task 1'!F$14,FALSE)) -> adding the income report generation to the cli | AA4: =IF(VLOOKUP($A4,'Task 1'!$A$2:$P$13,'Task 1'!G$14,FALSE)="","",VLOOKUP($A4,'Task 1'!$A$2:$P$13,'Task 1'!G$14,FALSE)) -> The agent seems to have troubles with python syntax, i.e., the indentation (IndentationError) | AB4: =IF(VLOOKUP($A4,'Task 1'!$A$2:$P$13,'Task 1'!H$14,FALSE)="","",VLOOKUP($A4,'Task 1'!$A$2:$P$13,'Task 1'!H$14,FALSE)) -> Yes, it does. It requests multiple times to “Create the 'IncomeTracker' class ... to satisfy the PR description", the commit titles also indicate this with multiple "Add income report generation to CLI" | AC4: =IF(VLOOKUP($A4,'Task 1'!$A$2:$P$13,'Task 1'!I$14,FALSE)="","",VLOOKUP($A4,'Task 1'!$A$2:$P$13,'Task 1'!I$14,FALSE)) -> import cmd 2 import argparse 3 from finance_tracker.expenses import ExpenseTracker 4 from finance_tracker.budgets import BudgetManager 5 from finance_tracker.users import UserManager 6 from finance_tracker.reports import FinancialReport 7 from finance_tracker.income import IncomeTracker 8 from datetime import datetime 9 10 class FinanceTrackerCLI(cmd.Cmd): 11 """Command-line interface for the finance tracker.""" 12 prompt = "FinanceTracker> " 13 intro = "Welcome to the Personal Finance Tracker. Type 'help' for commands." 14 15 def __init__(self): 16 super().__init__() 17 self.user_manager = UserManager() 18 self.current_user = None 19 self.expense_tracker = None 20 self.budget_manager = None 21 self.report_generator = None 22 23 def do_login(self, arg): 24 """Login to the system: login <username> <password>""" 25 args = arg.split() 26 if len(args) != 2: 27 print("Usage: login <username> <password>") 28 return 29 username, password = args 30 if self.user_manager.authenticate_user(username, password): 31 self.current_user = username 32 self.expense_tracker = ExpenseTracker(username) 33 self.budget_manager = BudgetManager(username) 34 self.report_generator = FinancialReport(username, self.expense_tracker, self.budget_manager) 35 print(f"Logged in as {username}") 36 else: 37 print("Invalid username or password") 38 39 def do_register(self, arg): 40 """Register a new user: register <username> <password> <email>""" 41 args = arg.split() 42 if len(args) != 3: 43 print("Usage: register <username> <password> <email>") 44 return 45 try: 46 self.user_manager.register_user(*args) 47 print(f"User {args[0]} registered successfully") 48 except ValueError as e: 49 print(f"Error: {e}") 50 51 def do_add_expense(self, arg): 52 """Add an expense: add_expense <amount> <category> <description> [tags] [recurring] [period]""" 53 if not self.current_user: 54 print("Please login first") 55 return 56 args = arg.split() 57 if len(args) < 3: 58 print("Usage: add_expense <amount> <category> <description> [tags] [recurring] [period]") 59 return 60 amount, category, description = args[:3] 61 tags = args[3].split(",") if len(args) > 3 else [] 62 is_recurring = args[4].lower() == "true" if len(args) > 4 else False 63 period = args[5] if len(args) > 5 else None 64 try: 65 expense_id = self.expense_tracker.add_expense(float(amount), category, description, 66 tags=tags, is_recurring=is_recurring, 67 recurrence_period=period) 68 print(f"Expense added with ID: {expense_id}") 69 except ValueError as e: 70 print(f"Error: {e}") 71 72 def do_set_budget(self, arg): 73 """Set a budget: set_budget <category> <amount> [period] [alert_threshold]""" 74 if not self.current_user: 75 print("Please login first") 76 return 77 args = arg.split() 78 if len(args) < 2: 79 print("Usage: set_budget <category> <amount> [period] [alert_threshold]") 80 return 81 category, amount = args[:2] 82 period = args[2] if len(args) > 2 else "monthly" 83 alert_threshold = float(args[3]) if len(args) > 3 else 0.8 84 try: 85 self.budget_manager.set_budget(category, float(amount), period, alert_threshold) 86 print(f"Budget set for {category} ({period})") 87 except ValueError as e: 88 print(f"Error: {e}") 89 90 def do_generate_report(self, arg): 91 """Generate a report: generate_report <type> [start_date] [end_date]""" 92 if not self.current_user: 93 print("Please login first") 94 return 95 args = arg.split() 96 if len(args) < 1: 97 print("Usage: generate_report <type> [start_date] [end_date]") 98 return 99 report_type = args[0] 100 start_date = args[1] if len(args) > 1 else None 101 end_date = args[2] if len(args) > 2 else None 102 try: 103 report_file = self.report_generator.generate_report_pdf(report_type, start_date, end_date) 104 print(f"Report generated: {report_file}") 105 except Exception as e: 106 print(f"Error: {e}") 107 108 def do_exit(self, arg): 109 """Exit the CLI.""" 110 print("Goodbye!") 111 return True 112 113 def preloop(self): 114 """Initialize CLI state.""" 115 print("Personal Finance Tracker CLI. Type 'register' or 'login' to begin.") | AD4: =IF(VLOOKUP($A4,'Task 1'!$A$2:$P$13,'Task 1'!J$14,FALSE)="","",VLOOKUP($A4,'Task 1'!$A$2:$P$13,'Task 1'!J$14,FALSE)) -> cli.py, report.py, income.py | ... AJ4: =IF(VLOOKUP($A4,'Task 1'!$A$2:$P$13,'Task 1'!P$14,FALSE)="","",VLOOKUP($A4,'Task 1'!$A$2:$P$13,'Task 1'!P$14,FALSE)) -> first test, then error so next "updated logic" | AK4: =IF(VLOOKUP($A4,Form_Responses8[[Participant Key]:[Find and describe all potential bugs!]],3,FALSE)="","",VLOOKUP($A4,Form_Responses8[[Participant Key]:[Find and describe all potential bugs!]],3,FALSE)) -> The LLM suggests to update the read method to account for both \r and \n characters, but the agent misinterprets it and removes the \n (which was correct), instead of adding a new if-case for \r. | AL4: =IF(VLOOKUP($A4,Form_Responses6[[Participant Key]:[Find and describe all potential bugs!]],3,FALSE)="","",VLOOKUP($A4,Form_Responses6[[Participant Key]:[Find and describe all potential bugs!]],3,FALSE)) -> The agent tries to use forbidden commands (for which it has no permission) multiple times. It also tries to chain commands, which also does not seem to work. The LLM suggests to write a dockerfile, but the agent runs into problems. The agent and LLM do not seem to recognize that they are running in circles. It seems like after "The agent acknowledges that the LLM's training data is current only until October 2023.", the agent loses its "history" and tries commands again which have not worked before. | AM4: {=INDEX('Task 1'!$B$30:$B$43,COLUMN(A3))} -> 3 | AN4: {=INDEX('Task 1'!$B$30:$B$43,COLUMN(B3))} -> 1 | AO4: {=INDEX('Task 1'!$B$30:$B$43,COLUMN(C3))} -> 2 | AP4: {=INDEX('Task 1'!$B$30:$B$43,COLUMN(D3))} -> 1 | AQ4: {=INDEX('Task 1'!$B$30:$B$43,COLUMN(E3))} -> 1 | AR4: {=INDEX('Task 1'!$B$30:$B$43,COLUMN(F3))} -> 2 | AS4: {=INDEX('Task 1'!$B$30:$B$43,COLUMN(G3))} -> 1 | AT4: {=INDEX('Task 1'!$B$30:$B$43,COLUMN(H3))} -> 2 | ... AZ4: {=INDEX('Task 1'!$B$30:$B$43,COLUMN(N3))} -> 2 | BA4: 1 | BB4: 1 | BC4: ='Task 1'!$B$45 -> 21 | BD4: ='Task 1'!$D$45 -> 84
A5: ='Task 1'!A51 -> 1d20 | B5: =VLOOKUP(A5,'Task 1'!A$48:B$59,2,FALSE) -> A | C5: =VLOOKUP($A5,'Task 1'!$A$16:$P$27,'Task 1'!C$14,FALSE) -> 1 | D5: =VLOOKUP($A5,'Task 1'!$A$16:$P$27,'Task 1'!D$14,FALSE) -> 1 | E5: =VLOOKUP($A5,'Task 1'!$A$16:$P$27,'Task 1'!E$14,FALSE) -> 2 | F5: =VLOOKUP($A5,'Task 1'!$A$16:$P$27,'Task 1'!F$14,FALSE) -> 1 | G5: =VLOOKUP($A5,'Task 1'!$A$16:$P$27,'Task 1'!G$14,FALSE) -> 1 | H5: =VLOOKUP($A5,'Task 1'!$A$16:$P$27,'Task 1'!H$14,FALSE) -> 1 | I5: =VLOOKUP($A5,'Task 1'!$A$16:$P$27,'Task 1'!I$14,FALSE) -> 1 | J5: =VLOOKUP($A5,'Task 1'!$A$16:$P$27,'Task 1'!J$14,FALSE) -> 1 | ... P5: =VLOOKUP($A5,'Task 1'!$A$16:$P$27,'Task 1'!P$14,FALSE) -> 1 | Q5: =VLOOKUP($A5,'Task 2'!$A$2:$J$12,10,FALSE) -> 1 | R5: =VLOOKUP($A5,'Task 3'!$A$2:$J$12,10,FALSE) -> 1 | S5: =VLOOKUP($A5,'Task 1'!$A$16:$V$27,17,FALSE) -> 16 | T5: =VLOOKUP($A5,'Task 1'!$A$16:$V$27,18,FALSE) -> 71 | U5: =VLOOKUP($A5,'Task 1'!$A$16:$V$27,19,FALSE) -> 0.8452381 | V5: =VLOOKUP($A5,'Task 1'!$A$16:$W$27,23,FALSE) -> 0.083333333 | W5: =IF(VLOOKUP($A5,'Task 1'!$A$2:$P$13,'Task 1'!C$14,FALSE)="","",VLOOKUP($A5,'Task 1'!$A$2:$P$13,'Task 1'!C$14,FALSE)) -> The goal is to implement a new feature as described by a PR description | X5: =IF(VLOOKUP($A5,'Task 1'!$A$2:$P$13,'Task 1'!D$14,FALSE)="","",VLOOKUP($A5,'Task 1'!$A$2:$P$13,'Task 1'!D$14,FALSE)) -> No, the task was not completed. | Y5: =IF(VLOOKUP($A5,'Task 1'!$A$2:$P$13,'Task 1'!E$14,FALSE)="","",VLOOKUP($A5,'Task 1'!$A$2:$P$13,'Task 1'!E$14,FALSE)) -> Listing contents of a directory, reading a file writing to a file, creating a new file, modifying a file via diff syntax, running bash commands | Z5: =IF(VLOOKUP($A5,'Task 1'!$A$2:$P$13,'Task 1'!F$14,FALSE)="","",VLOOKUP($A5,'Task 1'!$A$2:$P$13,'Task 1'!F$14,FALSE)) -> Modifying the contents of a file | AA5: =IF(VLOOKUP($A5,'Task 1'!$A$2:$P$13,'Task 1'!G$14,FALSE)="","",VLOOKUP($A5,'Task 1'!$A$2:$P$13,'Task 1'!G$14,FALSE)) -> The agent has trouble fixing a syntax error (the indentation error) | AB5: =IF(VLOOKUP($A5,'Task 1'!$A$2:$P$13,'Task 1'!H$14,FALSE)="","",VLOOKUP($A5,'Task 1'!$A$2:$P$13,'Task 1'!H$14,FALSE)) -> The agent modified a part of the code that was not the erroneous part of the code. It tried multiple times to fix the indentation error by modifying a different part of the code. | AC5: =IF(VLOOKUP($A5,'Task 1'!$A$2:$P$13,'Task 1'!I$14,FALSE)="","",VLOOKUP($A5,'Task 1'!$A$2:$P$13,'Task 1'!I$14,FALSE)) -> 7 + from finance_tracker.income import IncomeTracker | AD5: =IF(VLOOKUP($A5,'Task 1'!$A$2:$P$13,'Task 1'!J$14,FALSE)="","",VLOOKUP($A5,'Task 1'!$A$2:$P$13,'Task 1'!J$14,FALSE)) -> income.py, expenses.py, reports.py, cli.py | ... AJ5: =IF(VLOOKUP($A5,'Task 1'!$A$2:$P$13,'Task 1'!P$14,FALSE)="","",VLOOKUP($A5,'Task 1'!$A$2:$P$13,'Task 1'!P$14,FALSE)) -> They are all modifying the same location of the code, which is not the location that needs a fix. Their purpose is to fix the indentation error, but the edits are the same. | AK5: =IF(VLOOKUP($A5,Form_Responses8[[Participant Key]:[Find and describe all potential bugs!]],3,FALSE)="","",VLOOKUP($A5,Form_Responses8[[Participant Key]:[Find and describe all potential bugs!]],3,FALSE)) -> It seems that the tool implementation is buggy and when the agent tries to modify the file, the process does not work correctly. From my inspections the agent tries to modify something, but the resulting file contents are not as expected. | AL5: =IF(VLOOKUP($A5,Form_Responses6[[Participant Key]:[Find and describe all potential bugs!]],3,FALSE)="","",VLOOKUP($A5,Form_Responses6[[Participant Key]:[Find and describe all potential bugs!]],3,FALSE)) -> The main issue is that the agent was never able to create a working dockerfile to try different approaches to resolve the problem. The main problem I see in this trajectory is that the error message from one write to a dockerfile was not returned to the agent. The other logic problem that could exist is that the agent seems to not have a good instruction on that it has to first create a dockerfile to be able to run all bash commands. | AM5: {=INDEX('Task 1'!$B$30:$B$43,COLUMN(A4))} -> 3 | AN5: {=INDEX('Task 1'!$B$30:$B$43,COLUMN(B4))} -> 1 | AO5: {=INDEX('Task 1'!$B$30:$B$43,COLUMN(C4))} -> 2 | AP5: {=INDEX('Task 1'!$B$30:$B$43,COLUMN(D4))} -> 1 | AQ5: {=INDEX('Task 1'!$B$30:$B$43,COLUMN(E4))} -> 1 | AR5: {=INDEX('Task 1'!$B$30:$B$43,COLUMN(F4))} -> 2 | AS5: {=INDEX('Task 1'!$B$30:$B$43,COLUMN(G4))} -> 1 | AT5: {=INDEX('Task 1'!$B$30:$B$43,COLUMN(H4))} -> 2 | ... AZ5: {=INDEX('Task 1'!$B$30:$B$43,COLUMN(N4))} -> 2 | BA5: 1 | BB5: 1 | BC5: ='Task 1'!$B$45 -> 21 | BD5: ='Task 1'!$D$45 -> 84
A6: ='Task 1'!A52 -> 33c6 | B6: =VLOOKUP(A6,'Task 1'!A$48:B$59,2,FALSE) -> A | C6: =VLOOKUP($A6,'Task 1'!$A$16:$P$27,'Task 1'!C$14,FALSE) -> 1 | D6: =VLOOKUP($A6,'Task 1'!$A$16:$P$27,'Task 1'!D$14,FALSE) -> 1 | E6: =VLOOKUP($A6,'Task 1'!$A$16:$P$27,'Task 1'!E$14,FALSE) -> 2 | F6: =VLOOKUP($A6,'Task 1'!$A$16:$P$27,'Task 1'!F$14,FALSE) -> 1 | G6: =VLOOKUP($A6,'Task 1'!$A$16:$P$27,'Task 1'!G$14,FALSE) -> 1 | H6: =VLOOKUP($A6,'Task 1'!$A$16:$P$27,'Task 1'!H$14,FALSE) -> 2 | I6: =VLOOKUP($A6,'Task 1'!$A$16:$P$27,'Task 1'!I$14,FALSE) -> 1 | J6: =VLOOKUP($A6,'Task 1'!$A$16:$P$27,'Task 1'!J$14,FALSE) -> 1 | ... P6: =VLOOKUP($A6,'Task 1'!$A$16:$P$27,'Task 1'!P$14,FALSE) -> 1 | Q6: =VLOOKUP($A6,'Task 2'!$A$2:$J$12,10,FALSE) -> 1 | R6: =VLOOKUP($A6,'Task 3'!$A$2:$J$12,10,FALSE) -> 1 | S6: =VLOOKUP($A6,'Task 1'!$A$16:$V$27,17,FALSE) -> 17 | T6: =VLOOKUP($A6,'Task 1'!$A$16:$V$27,18,FALSE) -> 74 | U6: =VLOOKUP($A6,'Task 1'!$A$16:$V$27,19,FALSE) -> 0.88095238 | V6: =VLOOKUP($A6,'Task 1'!$A$16:$W$27,23,FALSE) -> 0 | W6: =IF(VLOOKUP($A6,'Task 1'!$A$2:$P$13,'Task 1'!C$14,FALSE)="","",VLOOKUP($A6,'Task 1'!$A$2:$P$13,'Task 1'!C$14,FALSE)) -> Implementing a feature as suggested by a pull request | X6: =IF(VLOOKUP($A6,'Task 1'!$A$2:$P$13,'Task 1'!D$14,FALSE)="","",VLOOKUP($A6,'Task 1'!$A$2:$P$13,'Task 1'!D$14,FALSE)) -> No, the task was not completed. | Y6: =IF(VLOOKUP($A6,'Task 1'!$A$2:$P$13,'Task 1'!E$14,FALSE)="","",VLOOKUP($A6,'Task 1'!$A$2:$P$13,'Task 1'!E$14,FALSE)) -> listing files, showing file content, make modifications to files, create files, execute tests, install dependencies | Z6: =IF(VLOOKUP($A6,'Task 1'!$A$2:$P$13,'Task 1'!F$14,FALSE)="","",VLOOKUP($A6,'Task 1'!$A$2:$P$13,'Task 1'!F$14,FALSE)) -> editing files | AA6: =IF(VLOOKUP($A6,'Task 1'!$A$2:$P$13,'Task 1'!G$14,FALSE)="","",VLOOKUP($A6,'Task 1'!$A$2:$P$13,'Task 1'!G$14,FALSE)) -> Trying to add code to generate an income report. After multiple tries of making this change the tests always fail with an IndentationError. | AB6: =IF(VLOOKUP($A6,'Task 1'!$A$2:$P$13,'Task 1'!H$14,FALSE)="","",VLOOKUP($A6,'Task 1'!$A$2:$P$13,'Task 1'!H$14,FALSE)) -> The agent adds the code for generating an income report 6 times in a row before execution ends. It is always the same code change. | AC6: =IF(VLOOKUP($A6,'Task 1'!$A$2:$P$13,'Task 1'!I$14,FALSE)="","",VLOOKUP($A6,'Task 1'!$A$2:$P$13,'Task 1'!I$14,FALSE)) -> object {2} tool : str_replace_editor str_replace /finance_tracker/finance_tracker/cli.py --old_str 'from finance_tracker.reports import FinancialReport' --new_str 'from finance_tracker.reports import FinancialReport\nfrom finance_tracker.income import IncomeTracker' args : null | AD6: =IF(VLOOKUP($A6,'Task 1'!$A$2:$P$13,'Task 1'!J$14,FALSE)="","",VLOOKUP($A6,'Task 1'!$A$2:$P$13,'Task 1'!J$14,FALSE)) -> cli.py, reports.py, expenses.py, income.py | ... AJ6: =IF(VLOOKUP($A6,'Task 1'!$A$2:$P$13,'Task 1'!P$14,FALSE)="","",VLOOKUP($A6,'Task 1'!$A$2:$P$13,'Task 1'!P$14,FALSE)) -> They are all making the same change to cli.py. | AK6: =IF(VLOOKUP($A6,Form_Responses8[[Participant Key]:[Find and describe all potential bugs!]],3,FALSE)="","",VLOOKUP($A6,Form_Responses8[[Participant Key]:[Find and describe all potential bugs!]],3,FALSE)) -> The LLM calls the write_fix tool with a meaningful fix trying to modify the line 58 to also handle other line endings. There seems to however be a bug in the implementation of applying the proposed fix to the repository. The file is not correctly modified but the line to modify is only removed. | AL6: =IF(VLOOKUP($A6,Form_Responses6[[Participant Key]:[Find and describe all potential bugs!]],3,FALSE)="","",VLOOKUP($A6,Form_Responses6[[Participant Key]:[Find and describe all potential bugs!]],3,FALSE)) -> At the beginning the LLM tries to run a bash command to setup openjdk eventhough it is not allowed to do this at that state. In the second tool call it tries to run an unallowed command. The third LLM response is empty as the LLM rejects the prompt. Similar problems occur multiple times. The agent continues to fail to create a script for seting up the docker environment. After a while the LLM is able to successfully call the tool to write a docker file, but the agent fails to start the docker image. It tries this multiple more times but it is not clear why it fails. | AM6: {=INDEX('Task 1'!$B$30:$B$43,COLUMN(A5))} -> 3 | AN6: {=INDEX('Task 1'!$B$30:$B$43,COLUMN(B5))} -> 1 | AO6: {=INDEX('Task 1'!$B$30:$B$43,COLUMN(C5))} -> 2 | AP6: {=INDEX('Task 1'!$B$30:$B$43,COLUMN(D5))} -> 1 | AQ6: {=INDEX('Task 1'!$B$30:$B$43,COLUMN(E5))} -> 1 | AR6: {=INDEX('Task 1'!$B$30:$B$43,COLUMN(F5))} -> 2 | AS6: {=INDEX('Task 1'!$B$30:$B$43,COLUMN(G5))} -> 1 | AT6: {=INDEX('Task 1'!$B$30:$B$43,COLUMN(H5))} -> 2 | ... AZ6: {=INDEX('Task 1'!$B$30:$B$43,COLUMN(N5))} -> 2 | BA6: 1 | BB6: 1 | BC6: ='Task 1'!$B$45 -> 21 | BD6: ='Task 1'!$D$45 -> 84
A7: ='Task 1'!A53 -> 49f7 | B7: =VLOOKUP(A7,'Task 1'!A$48:B$59,2,FALSE) -> B | C7: =VLOOKUP($A7,'Task 1'!$A$16:$P$27,'Task 1'!C$14,FALSE) -> 2 | D7: =VLOOKUP($A7,'Task 1'!$A$16:$P$27,'Task 1'!D$14,FALSE) -> 1 | E7: =VLOOKUP($A7,'Task 1'!$A$16:$P$27,'Task 1'!E$14,FALSE) -> 2 | F7: =VLOOKUP($A7,'Task 1'!$A$16:$P$27,'Task 1'!F$14,FALSE) -> 1 | G7: =VLOOKUP($A7,'Task 1'!$A$16:$P$27,'Task 1'!G$14,FALSE) -> 1 | H7: =VLOOKUP($A7,'Task 1'!$A$16:$P$27,'Task 1'!H$14,FALSE) -> 2 | I7: =VLOOKUP($A7,'Task 1'!$A$16:$P$27,'Task 1'!I$14,FALSE) -> 0 | J7: =VLOOKUP($A7,'Task 1'!$A$16:$P$27,'Task 1'!J$14,FALSE) -> 0 | ... P7: =VLOOKUP($A7,'Task 1'!$A$16:$P$27,'Task 1'!P$14,FALSE) -> 1 | Q7: =VLOOKUP($A7,'Task 2'!$A$2:$J$12,10,FALSE) -> 0 | R7: =VLOOKUP($A7,'Task 3'!$A$2:$J$12,10,FALSE) -> 1 | S7: =VLOOKUP($A7,'Task 1'!$A$16:$V$27,17,FALSE) -> 16 | T7: =VLOOKUP($A7,'Task 1'!$A$16:$V$27,18,FALSE) -> 67 | U7: =VLOOKUP($A7,'Task 1'!$A$16:$V$27,19,FALSE) -> 0.79761905 | V7: =VLOOKUP($A7,'Task 1'!$A$16:$W$27,23,FALSE) -> 0.16666667 | W7: =IF(VLOOKUP($A7,'Task 1'!$A$2:$P$13,'Task 1'!C$14,FALSE)="","",VLOOKUP($A7,'Task 1'!$A$2:$P$13,'Task 1'!C$14,FALSE)) -> The agents goal is to add an income tracking feature to a personal finance tracker written in python | X7: =IF(VLOOKUP($A7,'Task 1'!$A$2:$P$13,'Task 1'!D$14,FALSE)="","",VLOOKUP($A7,'Task 1'!$A$2:$P$13,'Task 1'!D$14,FALSE)) -> No, the task was not completed. | Y7: =IF(VLOOKUP($A7,'Task 1'!$A$2:$P$13,'Task 1'!E$14,FALSE)="","",VLOOKUP($A7,'Task 1'!$A$2:$P$13,'Task 1'!E$14,FALSE)) -> Listing directories (ls), printing file contents (cat), writing file contents (str_replace_editor), running program (python3) | Z7: =IF(VLOOKUP($A7,'Task 1'!$A$2:$P$13,'Task 1'!F$14,FALSE)="","",VLOOKUP($A7,'Task 1'!$A$2:$P$13,'Task 1'!F$14,FALSE)) -> str_replace_editor (replacing parts of a file) | AA7: =IF(VLOOKUP($A7,'Task 1'!$A$2:$P$13,'Task 1'!G$14,FALSE)="","",VLOOKUP($A7,'Task 1'!$A$2:$P$13,'Task 1'!G$14,FALSE)) -> It is unable to indent properly (IndentationError) | AB7: =IF(VLOOKUP($A7,'Task 1'!$A$2:$P$13,'Task 1'!H$14,FALSE)="","",VLOOKUP($A7,'Task 1'!$A$2:$P$13,'Task 1'!H$14,FALSE)) -> Yes, it keeps "replacing" the line ' def do_generate_income_report(self, arg):' in /finance_tracker/cli.py with the same value, not knowing that the actual problem is that 'def __init__(self):' has no proper body. | AC7: =IF(VLOOKUP($A7,'Task 1'!$A$2:$P$13,'Task 1'!I$14,FALSE)="","",VLOOKUP($A7,'Task 1'!$A$2:$P$13,'Task 1'!I$14,FALSE)) -> --- a/finance_tracker/cli.py +++ b/finance_tracker/cli.py @@ -4,6 +4,7 @@ from finance_tracker.expenses import ExpenseTracker from finance_tracker.budgets import BudgetManager from finance_tracker.users import UserManager from finance_tracker.reports import FinancialReport +from finance_tracker.income import IncomeTracker from datetime import datetime class FinanceTrackerCLI(cmd.Cmd): (str_replace_editor str_replace /finance_tracker/finance_tracker/cli.py --old_str 'from finance_tracker.reports import FinancialReport' --new_str 'from finance_tracker.reports import FinancialReport) | AD7: =IF(VLOOKUP($A7,'Task 1'!$A$2:$P$13,'Task 1'!J$14,FALSE)="","",VLOOKUP($A7,'Task 1'!$A$2:$P$13,'Task 1'!J$14,FALSE)) -> cli.py, README.md | ... AJ7: =IF(VLOOKUP($A7,'Task 1'!$A$2:$P$13,'Task 1'!P$14,FALSE)="","",VLOOKUP($A7,'Task 1'!$A$2:$P$13,'Task 1'!P$14,FALSE)) -> The agent does the same changes five times, sometimes running the test in between and sometimes not | AK7: =IF(VLOOKUP($A7,Form_Responses8[[Participant Key]:[Find and describe all potential bugs!]],3,FALSE)="","",VLOOKUP($A7,Form_Responses8[[Participant Key]:[Find and describe all potential bugs!]],3,FALSE)) -> Test 'org.apache.commons.csv.CSVParserTest::testGetLineNumberWithCR' fails. However, the agent only is shown code from code from 'org.apache.commons.csv.CSVParserTest::testGetLineNumberWithCRLF' | AL7: =IF(VLOOKUP($A7,Form_Responses6[[Participant Key]:[Find and describe all potential bugs!]],3,FALSE)="","",VLOOKUP($A7,Form_Responses6[[Participant Key]:[Find and describe all potential bugs!]],3,FALSE)) -> Docker commands are not allowed on the system. The agent is told upfront that this is not possible, but it does it anyways. At first, it correctly uses write_to_file instead, but when the docker container fails to start for an unspecified reason, the agent tries to "escape" into a new shell that does not have this restriction or issues with the docker command. That is prohibited as well. ... | AM7: {=INDEX('Task 1'!$B$30:$B$43,COLUMN(A6))} -> 3 | AN7: {=INDEX('Task 1'!$B$30:$B$43,COLUMN(B6))} -> 1 | AO7: {=INDEX('Task 1'!$B$30:$B$43,COLUMN(C6))} -> 2 | AP7: {=INDEX('Task 1'!$B$30:$B$43,COLUMN(D6))} -> 1 | AQ7: {=INDEX('Task 1'!$B$30:$B$43,COLUMN(E6))} -> 1 | AR7: {=INDEX('Task 1'!$B$30:$B$43,COLUMN(F6))} -> 2 | AS7: {=INDEX('Task 1'!$B$30:$B$43,COLUMN(G6))} -> 1 | AT7: {=INDEX('Task 1'!$B$30:$B$43,COLUMN(H6))} -> 2 | ... AZ7: {=INDEX('Task 1'!$B$30:$B$43,COLUMN(N6))} -> 2 | BA7: 1 | BB7: 1 | BC7: ='Task 1'!$B$45 -> 21 | BD7: ='Task 1'!$D$45 -> 84
A8: ='Task 1'!A54 -> 536e | B8: =VLOOKUP(A8,'Task 1'!A$48:B$59,2,FALSE) -> A | C8: =VLOOKUP($A8,'Task 1'!$A$16:$P$27,'Task 1'!C$14,FALSE) -> 2 | D8: =VLOOKUP($A8,'Task 1'!$A$16:$P$27,'Task 1'!D$14,FALSE) -> 0 | E8: =VLOOKUP($A8,'Task 1'!$A$16:$P$27,'Task 1'!E$14,FALSE) -> 2 | F8: =VLOOKUP($A8,'Task 1'!$A$16:$P$27,'Task 1'!F$14,FALSE) -> 0 | G8: =VLOOKUP($A8,'Task 1'!$A$16:$P$27,'Task 1'!G$14,FALSE) -> 1 | H8: =VLOOKUP($A8,'Task 1'!$A$16:$P$27,'Task 1'!H$14,FALSE) -> 0 | I8: =VLOOKUP($A8,'Task 1'!$A$16:$P$27,'Task 1'!I$14,FALSE) -> 1 | J8: =VLOOKUP($A8,'Task 1'!$A$16:$P$27,'Task 1'!J$14,FALSE) -> 0 | ... P8: =VLOOKUP($A8,'Task 1'!$A$16:$P$27,'Task 1'!P$14,FALSE) -> 0 | Q8: =VLOOKUP($A8,'Task 2'!$A$2:$J$12,10,FALSE) -> 0 | R8: =VLOOKUP($A8,'Task 3'!$A$2:$J$12,10,FALSE) -> 0 | S8: =VLOOKUP($A8,'Task 1'!$A$16:$V$27,17,FALSE) -> 6 | T8: =VLOOKUP($A8,'Task 1'!$A$16:$V$27,18,FALSE) -> 22 | U8: =VLOOKUP($A8,'Task 1'!$A$16:$V$27,19,FALSE) -> 0.26190476 | V8: =VLOOKUP($A8,'Task 1'!$A$16:$W$27,23,FALSE) -> 0.75 | W8: =IF(VLOOKUP($A8,'Task 1'!$A$2:$P$13,'Task 1'!C$14,FALSE)="","",VLOOKUP($A8,'Task 1'!$A$2:$P$13,'Task 1'!C$14,FALSE)) -> income tracking feature as detailed in the PR description for the finance tracker project | X8: =IF(VLOOKUP($A8,'Task 1'!$A$2:$P$13,'Task 1'!D$14,FALSE)="","",VLOOKUP($A8,'Task 1'!$A$2:$P$13,'Task 1'!D$14,FALSE)) -> Yes, the task was completed successfully. | Y8: =IF(VLOOKUP($A8,'Task 1'!$A$2:$P$13,'Task 1'!E$14,FALSE)="","",VLOOKUP($A8,'Task 1'!$A$2:$P$13,'Task 1'!E$14,FALSE)) -> execute bash commands, tool call, file reading, update function | Z8: =IF(VLOOKUP($A8,'Task 1'!$A$2:$P$13,'Task 1'!F$14,FALSE)="","",VLOOKUP($A8,'Task 1'!$A$2:$P$13,'Task 1'!F$14,FALSE)) -> tool call | AA8: =IF(VLOOKUP($A8,'Task 1'!$A$2:$P$13,'Task 1'!G$14,FALSE)="","",VLOOKUP($A8,'Task 1'!$A$2:$P$13,'Task 1'!G$14,FALSE)) -> IndentationError, indicating a syntax error | AB8: =IF(VLOOKUP($A8,'Task 1'!$A$2:$P$13,'Task 1'!H$14,FALSE)="","",VLOOKUP($A8,'Task 1'!$A$2:$P$13,'Task 1'!H$14,FALSE)) -> Yes, he wanted to create a IncomeTracker class with different descriptions | AC8: =IF(VLOOKUP($A8,'Task 1'!$A$2:$P$13,'Task 1'!I$14,FALSE)="","",VLOOKUP($A8,'Task 1'!$A$2:$P$13,'Task 1'!I$14,FALSE)) -> replace a string in the File, altering the import statement for FinancialReport and adding IncomeTracker | AD8: =IF(VLOOKUP($A8,'Task 1'!$A$2:$P$13,'Task 1'!J$14,FALSE)="","",VLOOKUP($A8,'Task 1'!$A$2:$P$13,'Task 1'!J$14,FALSE)) -> report.py | ... AJ8: =IF(VLOOKUP($A8,'Task 1'!$A$2:$P$13,'Task 1'!P$14,FALSE)="","",VLOOKUP($A8,'Task 1'!$A$2:$P$13,'Task 1'!P$14,FALSE)) | AK8: =IF(VLOOKUP($A8,Form_Responses8[[Participant Key]:[Find and describe all potential bugs!]],3,FALSE)="","",VLOOKUP($A8,Form_Responses8[[Participant Key]:[Find and describe all potential bugs!]],3,FALSE)) -> The fix description from the agent isnt good enough for the LLM. | AL8: =IF(VLOOKUP($A8,Form_Responses6[[Participant Key]:[Find and describe all potential bugs!]],3,FALSE)="","",VLOOKUP($A8,Form_Responses6[[Participant Key]:[Find and describe all potential bugs!]],3,FALSE)) -> The command line could not handle the agents input. It repeats it self. | AM8: {=INDEX('Task 1'!$B$30:$B$43,COLUMN(A7))} -> 3 | AN8: {=INDEX('Task 1'!$B$30:$B$43,COLUMN(B7))} -> 1 | AO8: {=INDEX('Task 1'!$B$30:$B$43,COLUMN(C7))} -> 2 | AP8: {=INDEX('Task 1'!$B$30:$B$43,COLUMN(D7))} -> 1 | AQ8: {=INDEX('Task 1'!$B$30:$B$43,COLUMN(E7))} -> 1 | AR8: {=INDEX('Task 1'!$B$30:$B$43,COLUMN(F7))} -> 2 | AS8: {=INDEX('Task 1'!$B$30:$B$43,COLUMN(G7))} -> 1 | AT8: {=INDEX('Task 1'!$B$30:$B$43,COLUMN(H7))} -> 2 | ... AZ8: {=INDEX('Task 1'!$B$30:$B$43,COLUMN(N7))} -> 2 | BA8: 1 | BB8: 1 | BC8: ='Task 1'!$B$45 -> 21 | BD8: ='Task 1'!$D$45 -> 84
A9: ='Task 1'!A55 -> 5694 | B9: =VLOOKUP(A9,'Task 1'!A$48:B$59,2,FALSE) -> B | C9: =VLOOKUP($A9,'Task 1'!$A$16:$P$27,'Task 1'!C$14,FALSE) -> 3 | D9: =VLOOKUP($A9,'Task 1'!$A$16:$P$27,'Task 1'!D$14,FALSE) -> 1 | E9: =VLOOKUP($A9,'Task 1'!$A$16:$P$27,'Task 1'!E$14,FALSE) -> 1 | F9: =VLOOKUP($A9,'Task 1'!$A$16:$P$27,'Task 1'!F$14,FALSE) -> 0 | G9: =VLOOKUP($A9,'Task 1'!$A$16:$P$27,'Task 1'!G$14,FALSE) -> 0 | H9: =VLOOKUP($A9,'Task 1'!$A$16:$P$27,'Task 1'!H$14,FALSE) -> 0 | I9: =VLOOKUP($A9,'Task 1'!$A$16:$P$27,'Task 1'!I$14,FALSE) -> 0 | J9: =VLOOKUP($A9,'Task 1'!$A$16:$P$27,'Task 1'!J$14,FALSE) -> 0 | ... P9: =VLOOKUP($A9,'Task 1'!$A$16:$P$27,'Task 1'!P$14,FALSE) -> 0 | Q9: =VLOOKUP($A9,'Task 2'!$A$2:$J$12,10,FALSE) -> 0 | R9: =VLOOKUP($A9,'Task 3'!$A$2:$J$12,10,FALSE) -> 0 | S9: =VLOOKUP($A9,'Task 1'!$A$16:$V$27,17,FALSE) -> 9 | T9: =VLOOKUP($A9,'Task 1'!$A$16:$V$27,18,FALSE) -> 36 | U9: =VLOOKUP($A9,'Task 1'!$A$16:$V$27,19,FALSE) -> 0.42857143 | V9: =VLOOKUP($A9,'Task 1'!$A$16:$W$27,23,FALSE) -> 0.66666667 | W9: =IF(VLOOKUP($A9,'Task 1'!$A$2:$P$13,'Task 1'!C$14,FALSE)="","",VLOOKUP($A9,'Task 1'!$A$2:$P$13,'Task 1'!C$14,FALSE)) -> Enhance the `finance_tracker` project by adding income tracking functionality to complement the existing expense, budget, user, and reporting features. The feature allows users to record income sources, track income by category and date, calculate net balance, and integrate with reporting and CLI. | X9: =IF(VLOOKUP($A9,'Task 1'!$A$2:$P$13,'Task 1'!D$14,FALSE)="","",VLOOKUP($A9,'Task 1'!$A$2:$P$13,'Task 1'!D$14,FALSE)) -> No, the task was not completed. | Y9: =IF(VLOOKUP($A9,'Task 1'!$A$2:$P$13,'Task 1'!E$14,FALSE)="","",VLOOKUP($A9,'Task 1'!$A$2:$P$13,'Task 1'!E$14,FALSE)) -> Observations, replacements, package installation | Z9: =IF(VLOOKUP($A9,'Task 1'!$A$2:$P$13,'Task 1'!F$14,FALSE)="","",VLOOKUP($A9,'Task 1'!$A$2:$P$13,'Task 1'!F$14,FALSE)) -> Observations | AA9: =IF(VLOOKUP($A9,'Task 1'!$A$2:$P$13,'Task 1'!G$14,FALSE)="","",VLOOKUP($A9,'Task 1'!$A$2:$P$13,'Task 1'!G$14,FALSE)) -> FunctionCallingFormatError | AB9: =IF(VLOOKUP($A9,'Task 1'!$A$2:$P$13,'Task 1'!H$14,FALSE)="","",VLOOKUP($A9,'Task 1'!$A$2:$P$13,'Task 1'!H$14,FALSE)) -> The Agent requeries the model 3 times in a row after a FunctionCallingFormatError | AC9: =IF(VLOOKUP($A9,'Task 1'!$A$2:$P$13,'Task 1'!I$14,FALSE)="","",VLOOKUP($A9,'Task 1'!$A$2:$P$13,'Task 1'!I$14,FALSE)) -> - `add_income <amount> <category> <description> [tags] [recurring] [period]` - `generate_income_report [start_date] [end_date]` | AD9: =IF(VLOOKUP($A9,'Task 1'!$A$2:$P$13,'Task 1'!J$14,FALSE)="","",VLOOKUP($A9,'Task 1'!$A$2:$P$13,'Task 1'!J$14,FALSE)) -> cli.py, README.md | ... AJ9: =IF(VLOOKUP($A9,'Task 1'!$A$2:$P$13,'Task 1'!P$14,FALSE)="","",VLOOKUP($A9,'Task 1'!$A$2:$P$13,'Task 1'!P$14,FALSE)) -> The Agent compares two different versions of the cli.py file | AK9: =IF(VLOOKUP($A9,Form_Responses8[[Participant Key]:[Find and describe all potential bugs!]],3,FALSE)="","",VLOOKUP($A9,Form_Responses8[[Participant Key]:[Find and describe all potential bugs!]],3,FALSE)) -> it proposes the same fix over and over again. | AL9: =IF(VLOOKUP($A9,Form_Responses6[[Participant Key]:[Find and describe all potential bugs!]],3,FALSE)="","",VLOOKUP($A9,Form_Responses6[[Participant Key]:[Find and describe all potential bugs!]],3,FALSE)) -> Problem: it seems that the files which should be read have invalid syntax. The Agent is does not seem to be able to fix it... Potential Bug: The Bug seems to be related with java, maybe the installation failed, or java is not yet a environment variable. | AM9: {=INDEX('Task 1'!$B$30:$B$43,COLUMN(A8))} -> 3 | AN9: {=INDEX('Task 1'!$B$30:$B$43,COLUMN(B8))} -> 1 | AO9: {=INDEX('Task 1'!$B$30:$B$43,COLUMN(C8))} -> 2 | AP9: {=INDEX('Task 1'!$B$30:$B$43,COLUMN(D8))} -> 1 | AQ9: {=INDEX('Task 1'!$B$30:$B$43,COLUMN(E8))} -> 1 | AR9: {=INDEX('Task 1'!$B$30:$B$43,COLUMN(F8))} -> 2 | AS9: {=INDEX('Task 1'!$B$30:$B$43,COLUMN(G8))} -> 1 | AT9: {=INDEX('Task 1'!$B$30:$B$43,COLUMN(H8))} -> 2 | ... AZ9: {=INDEX('Task 1'!$B$30:$B$43,COLUMN(N8))} -> 2 | BA9: 1 | BB9: 1 | BC9: ='Task 1'!$B$45 -> 21 | BD9: ='Task 1'!$D$45 -> 84
A10: ='Task 1'!A56 -> bdb6 | B10: =VLOOKUP(A10,'Task 1'!A$48:B$59,2,FALSE) -> B | C10: =VLOOKUP($A10,'Task 1'!$A$16:$P$27,'Task 1'!C$14,FALSE) -> 0 | D10: =VLOOKUP($A10,'Task 1'!$A$16:$P$27,'Task 1'!D$14,FALSE) -> 1 | E10: =VLOOKUP($A10,'Task 1'!$A$16:$P$27,'Task 1'!E$14,FALSE) -> 2 | F10: =VLOOKUP($A10,'Task 1'!$A$16:$P$27,'Task 1'!F$14,FALSE) -> 0 | G10: =VLOOKUP($A10,'Task 1'!$A$16:$P$27,'Task 1'!G$14,FALSE) -> 1 | H10: =VLOOKUP($A10,'Task 1'!$A$16:$P$27,'Task 1'!H$14,FALSE) -> 2 | I10: =VLOOKUP($A10,'Task 1'!$A$16:$P$27,'Task 1'!I$14,FALSE) -> 1 | J10: =VLOOKUP($A10,'Task 1'!$A$16:$P$27,'Task 1'!J$14,FALSE) -> 0 | ... P10: =VLOOKUP($A10,'Task 1'!$A$16:$P$27,'Task 1'!P$14,FALSE) -> 1 | Q10: =VLOOKUP($A10,'Task 2'!$A$2:$J$12,10,FALSE) -> 0 | R10: =VLOOKUP($A10,'Task 3'!$A$2:$J$12,10,FALSE) -> 0 | S10: =VLOOKUP($A10,'Task 1'!$A$16:$V$27,17,FALSE) -> 14 | T10: =VLOOKUP($A10,'Task 1'!$A$16:$V$27,18,FALSE) -> 63 | U10: =VLOOKUP($A10,'Task 1'!$A$16:$V$27,19,FALSE) -> 0.75 | V10: =VLOOKUP($A10,'Task 1'!$A$16:$W$27,23,FALSE) -> 0.25 | W10: =IF(VLOOKUP($A10,'Task 1'!$A$2:$P$13,'Task 1'!C$14,FALSE)="","",VLOOKUP($A10,'Task 1'!$A$2:$P$13,'Task 1'!C$14,FALSE)) -> It's a helpful assistant that can interact with a computer to solve tasks. | X10: =IF(VLOOKUP($A10,'Task 1'!$A$2:$P$13,'Task 1'!D$14,FALSE)="","",VLOOKUP($A10,'Task 1'!$A$2:$P$13,'Task 1'!D$14,FALSE)) -> No, the task was not completed. | Y10: =IF(VLOOKUP($A10,'Task 1'!$A$2:$P$13,'Task 1'!E$14,FALSE)="","",VLOOKUP($A10,'Task 1'!$A$2:$P$13,'Task 1'!E$14,FALSE)) -> ls, cat, str_replace_editor, python3 | Z10: =IF(VLOOKUP($A10,'Task 1'!$A$2:$P$13,'Task 1'!F$14,FALSE)="","",VLOOKUP($A10,'Task 1'!$A$2:$P$13,'Task 1'!F$14,FALSE)) -> cat | AA10: =IF(VLOOKUP($A10,'Task 1'!$A$2:$P$13,'Task 1'!G$14,FALSE)="","",VLOOKUP($A10,'Task 1'!$A$2:$P$13,'Task 1'!G$14,FALSE)) -> IndentationError: expected an indented block after function definition on line 40 | AB10: =IF(VLOOKUP($A10,'Task 1'!$A$2:$P$13,'Task 1'!H$14,FALSE)="","",VLOOKUP($A10,'Task 1'!$A$2:$P$13,'Task 1'!H$14,FALSE)) -> The agent calls ls /finance_tracker/finance_tracker three times in succession, resulting in WARNING | AC10: =IF(VLOOKUP($A10,'Task 1'!$A$2:$P$13,'Task 1'!I$14,FALSE)="","",VLOOKUP($A10,'Task 1'!$A$2:$P$13,'Task 1'!I$14,FALSE)) -> str_replace_editor str_replace /finance_tracker/finance_tracker/cli.py --old_str 'from finance_tracker.reports import FinancialReport' --new_str 'from finance_tracker.reports import FinancialReport | AD10: =IF(VLOOKUP($A10,'Task 1'!$A$2:$P$13,'Task 1'!J$14,FALSE)="","",VLOOKUP($A10,'Task 1'!$A$2:$P$13,'Task 1'!J$14,FALSE)) -> /finance_tracker/finance_tracker/cli.py | ... AJ10: =IF(VLOOKUP($A10,'Task 1'!$A$2:$P$13,'Task 1'!P$14,FALSE)="","",VLOOKUP($A10,'Task 1'!$A$2:$P$13,'Task 1'!P$14,FALSE)) -> They are the exact same change | AK10: =IF(VLOOKUP($A10,Form_Responses8[[Participant Key]:[Find and describe all potential bugs!]],3,FALSE)="","",VLOOKUP($A10,Form_Responses8[[Participant Key]:[Find and describe all potential bugs!]],3,FALSE)) -> I do not see an fatal bug but continued warning of repetition detected! with repeated write_fix seems concerning. The core should give more drastic guidance or the warning is not effective. | AL10: =IF(VLOOKUP($A10,Form_Responses6[[Participant Key]:[Find and describe all potential bugs!]],3,FALSE)="","",VLOOKUP($A10,Form_Responses6[[Participant Key]:[Find and describe all potential bugs!]],3,FALSE)) -> I don't see any obvious problem with agent's logic. | AM10: {=INDEX('Task 1'!$B$30:$B$43,COLUMN(A9))} -> 3 | AN10: {=INDEX('Task 1'!$B$30:$B$43,COLUMN(B9))} -> 1 | AO10: {=INDEX('Task 1'!$B$30:$B$43,COLUMN(C9))} -> 2 | AP10: {=INDEX('Task 1'!$B$30:$B$43,COLUMN(D9))} -> 1 | AQ10: {=INDEX('Task 1'!$B$30:$B$43,COLUMN(E9))} -> 1 | AR10: {=INDEX('Task 1'!$B$30:$B$43,COLUMN(F9))} -> 2 | AS10: {=INDEX('Task 1'!$B$30:$B$43,COLUMN(G9))} -> 1 | AT10: {=INDEX('Task 1'!$B$30:$B$43,COLUMN(H9))} -> 2 | ... AZ10: {=INDEX('Task 1'!$B$30:$B$43,COLUMN(N9))} -> 2 | BA10: 1 | BB10: 1 | BC10: ='Task 1'!$B$45 -> 21 | BD10: ='Task 1'!$D$45 -> 84
A11: ='Task 1'!A57 -> bdf7 | B11: =VLOOKUP(A11,'Task 1'!A$48:B$59,2,FALSE) -> A | C11: =VLOOKUP($A11,'Task 1'!$A$16:$P$27,'Task 1'!C$14,FALSE) -> 0 | D11: =VLOOKUP($A11,'Task 1'!$A$16:$P$27,'Task 1'!D$14,FALSE) -> 1 | E11: =VLOOKUP($A11,'Task 1'!$A$16:$P$27,'Task 1'!E$14,FALSE) -> 2 | F11: =VLOOKUP($A11,'Task 1'!$A$16:$P$27,'Task 1'!F$14,FALSE) -> 1 | G11: =VLOOKUP($A11,'Task 1'!$A$16:$P$27,'Task 1'!G$14,FALSE) -> 0 | H11: =VLOOKUP($A11,'Task 1'!$A$16:$P$27,'Task 1'!H$14,FALSE) -> 0 | I11: =VLOOKUP($A11,'Task 1'!$A$16:$P$27,'Task 1'!I$14,FALSE) -> 0 | J11: =VLOOKUP($A11,'Task 1'!$A$16:$P$27,'Task 1'!J$14,FALSE) -> 0 | ... P11: =VLOOKUP($A11,'Task 1'!$A$16:$P$27,'Task 1'!P$14,FALSE) -> 0 | Q11: =VLOOKUP($A11,'Task 2'!$A$2:$J$12,10,FALSE) -> 1 | R11: =VLOOKUP($A11,'Task 3'!$A$2:$J$12,10,FALSE) -> 0 | S11: =VLOOKUP($A11,'Task 1'!$A$16:$V$27,17,FALSE) -> 4 | T11: =VLOOKUP($A11,'Task 1'!$A$16:$V$27,18,FALSE) -> 18 | U11: =VLOOKUP($A11,'Task 1'!$A$16:$V$27,19,FALSE) -> 0.21428571 | V11: =VLOOKUP($A11,'Task 1'!$A$16:$W$27,23,FALSE) -> 0.83333333 | W11: =IF(VLOOKUP($A11,'Task 1'!$A$2:$P$13,'Task 1'!C$14,FALSE)="","",VLOOKUP($A11,'Task 1'!$A$2:$P$13,'Task 1'!C$14,FALSE)) -> The agent's goal is to implement an finance tracker application by creating and testing the required functionalities. | X11: =IF(VLOOKUP($A11,'Task 1'!$A$2:$P$13,'Task 1'!D$14,FALSE)="","",VLOOKUP($A11,'Task 1'!$A$2:$P$13,'Task 1'!D$14,FALSE)) -> No, the task was not completed. | Y11: =IF(VLOOKUP($A11,'Task 1'!$A$2:$P$13,'Task 1'!E$14,FALSE)="","",VLOOKUP($A11,'Task 1'!$A$2:$P$13,'Task 1'!E$14,FALSE)) -> Read content, Implement code, Test code, and fix code | Z11: =IF(VLOOKUP($A11,'Task 1'!$A$2:$P$13,'Task 1'!F$14,FALSE)="","",VLOOKUP($A11,'Task 1'!$A$2:$P$13,'Task 1'!F$14,FALSE)) -> Fix code | AA11: =IF(VLOOKUP($A11,'Task 1'!$A$2:$P$13,'Task 1'!G$14,FALSE)="","",VLOOKUP($A11,'Task 1'!$A$2:$P$13,'Task 1'!G$14,FALSE)) -> The agent has trouble implementing a correct version of the income tracker | AB11: =IF(VLOOKUP($A11,'Task 1'!$A$2:$P$13,'Task 1'!H$14,FALSE)="","",VLOOKUP($A11,'Task 1'!$A$2:$P$13,'Task 1'!H$14,FALSE)) -> Create the `IncomeTracker` class in `income.py` and update related files in the `finance_tracker` directory to incorporate income tracking features as outlined in the PR description. | AC11: =IF(VLOOKUP($A11,'Task 1'!$A$2:$P$13,'Task 1'!I$14,FALSE)="","",VLOOKUP($A11,'Task 1'!$A$2:$P$13,'Task 1'!I$14,FALSE)) -> The file /finance_tracker/finance_tracker/cli.py has been edited. Here's the result of running `cat -n` on a snippet of /finance_tracker/finance_tracker/cli.py: The file /finance_tracker/finance_tracker/reports.py has been edited. Here's the result of running `cat -n` on a snippet of /finance_tracker/finance_tracker/reports.py: 1 import cmd 32 "period": f"{start_date or 'all'} to {end_date or 'all'}", 2 import argparse 33 "category_totals": categories, 3 from finance_tracker.expenses import ExpenseTracker 34 "total": sum(categories.values()) 4 from finance_tracker.budgets import BudgetManager 35 } 5 from finance_tracker.users import UserManager 36 6 from finance_tracker.reports import FinancialReport 37 def generate_income_summary(self, start_date: str = None, end_date: str = None) -> Dict: 7 from finance_tracker.income import IncomeTracker 38 """Generate a summary of income by category.""" 8 from datetime import datetime 39 incomes = self.income_tracker.incomes 9 40 if start_date and end_date: 10 class FinanceTrackerCLI(cmd.Cmd): 41 incomes = [inc for inc in incomes if start_date <= inc.date <= end_date] 42 categories = {} 43 for inc in incomes: 44 cat = inc.category 45 categories[cat] = categories.get(cat, 0.0) + inc.amount 46 return { 47 "user_id": self.user_id, 48 "period": f"{start_date or 'all'} to {end_date or 'all'}", 49 "category_totals": categories, 50 "total": sum(categories.values()) 51 } 52 53 def generate_budget_comparison(self, period: str = "monthly") -> List[Dict]: 54 """Compare spending against budgets.""" 55 budgets = self.budget_manager.get_all_budgets() 56 comparison = [] Review the changes and make sure they are as expected. Edit the file again if necessary. Review the changes and make sure they are as expected. Edit the file again if necessary. | AD11: =IF(VLOOKUP($A11,'Task 1'!$A$2:$P$13,'Task 1'!J$14,FALSE)="","",VLOOKUP($A11,'Task 1'!$A$2:$P$13,'Task 1'!J$14,FALSE)) -> cli.py | ... AJ11: =IF(VLOOKUP($A11,'Task 1'!$A$2:$P$13,'Task 1'!P$14,FALSE)="","",VLOOKUP($A11,'Task 1'!$A$2:$P$13,'Task 1'!P$14,FALSE)) | AK11: =IF(VLOOKUP($A11,Form_Responses8[[Participant Key]:[Find and describe all potential bugs!]],3,FALSE)="","",VLOOKUP($A11,Form_Responses8[[Participant Key]:[Find and describe all potential bugs!]],3,FALSE)) -> The agent calls the write_fix tool to fix the problem but nothing is changed | AL11: =IF(VLOOKUP($A11,Form_Responses6[[Participant Key]:[Find and describe all potential bugs!]],3,FALSE)="","",VLOOKUP($A11,Form_Responses6[[Participant Key]:[Find and describe all potential bugs!]],3,FALSE)) -> The agent executes commands that are not available or allowed | AM11: {=INDEX('Task 1'!$B$30:$B$43,COLUMN(A10))} -> 3 | AN11: {=INDEX('Task 1'!$B$30:$B$43,COLUMN(B10))} -> 1 | AO11: {=INDEX('Task 1'!$B$30:$B$43,COLUMN(C10))} -> 2 | AP11: {=INDEX('Task 1'!$B$30:$B$43,COLUMN(D10))} -> 1 | AQ11: {=INDEX('Task 1'!$B$30:$B$43,COLUMN(E10))} -> 1 | AR11: {=INDEX('Task 1'!$B$30:$B$43,COLUMN(F10))} -> 2 | AS11: {=INDEX('Task 1'!$B$30:$B$43,COLUMN(G10))} -> 1 | AT11: {=INDEX('Task 1'!$B$30:$B$43,COLUMN(H10))} -> 2 | ... AZ11: {=INDEX('Task 1'!$B$30:$B$43,COLUMN(N10))} -> 2 | BA11: 1 | BB11: 1 | BC11: ='Task 1'!$B$45 -> 21 | BD11: ='Task 1'!$D$45 -> 84
A12: ='Task 1'!A58 -> 18e7 | B12: =VLOOKUP(A12,'Task 1'!A$48:B$59,2,FALSE) -> A | C12: =VLOOKUP($A12,'Task 1'!$A$16:$P$27,'Task 1'!C$14,FALSE) -> 2 | D12: =VLOOKUP($A12,'Task 1'!$A$16:$P$27,'Task 1'!D$14,FALSE) -> 0 | E12: =VLOOKUP($A12,'Task 1'!$A$16:$P$27,'Task 1'!E$14,FALSE) -> 2 | F12: =VLOOKUP($A12,'Task 1'!$A$16:$P$27,'Task 1'!F$14,FALSE) -> 1 | G12: =VLOOKUP($A12,'Task 1'!$A$16:$P$27,'Task 1'!G$14,FALSE) -> 1 | H12: =VLOOKUP($A12,'Task 1'!$A$16:$P$27,'Task 1'!H$14,FALSE) -> 2 | I12: =VLOOKUP($A12,'Task 1'!$A$16:$P$27,'Task 1'!I$14,FALSE) -> 0 | J12: =VLOOKUP($A12,'Task 1'!$A$16:$P$27,'Task 1'!J$14,FALSE) -> 1 | ... P12: =VLOOKUP($A12,'Task 1'!$A$16:$P$27,'Task 1'!P$14,FALSE) -> 1 | Q12: =VLOOKUP($A12,'Task 2'!$A$2:$J$12,10,FALSE) -> #N/A | R12: =VLOOKUP($A12,'Task 3'!$A$2:$J$12,10,FALSE) -> #N/A | S12: =VLOOKUP($A12,'Task 1'!$A$16:$V$27,17,FALSE) -> 15 | T12: =VLOOKUP($A12,'Task 1'!$A$16:$V$27,18,FALSE) -> 58 | U12: =VLOOKUP($A12,'Task 1'!$A$16:$V$27,19,FALSE) -> 0.69047619 | V12: =VLOOKUP($A12,'Task 1'!$A$16:$W$27,23,FALSE) -> 0.33333333 | W12: =IF(VLOOKUP($A12,'Task 1'!$A$2:$P$13,'Task 1'!C$14,FALSE)="","",VLOOKUP($A12,'Task 1'!$A$2:$P$13,'Task 1'!C$14,FALSE)) -> The agent goal is to implement new feature or new function-ality- that was described in the PR specifically the income tracking feature for a finance tracker project. | X12: =IF(VLOOKUP($A12,'Task 1'!$A$2:$P$13,'Task 1'!D$14,FALSE)="","",VLOOKUP($A12,'Task 1'!$A$2:$P$13,'Task 1'!D$14,FALSE)) -> Yes, the task was completed successfully. | Y12: =IF(VLOOKUP($A12,'Task 1'!$A$2:$P$13,'Task 1'!E$14,FALSE)="","",VLOOKUP($A12,'Task 1'!$A$2:$P$13,'Task 1'!E$14,FALSE)) -> File editing, File listing, Executing commands such as execute script and install package | Z12: =IF(VLOOKUP($A12,'Task 1'!$A$2:$P$13,'Task 1'!F$14,FALSE)="","",VLOOKUP($A12,'Task 1'!$A$2:$P$13,'Task 1'!F$14,FALSE)) -> File editing | AA12: =IF(VLOOKUP($A12,'Task 1'!$A$2:$P$13,'Task 1'!G$14,FALSE)="","",VLOOKUP($A12,'Task 1'!$A$2:$P$13,'Task 1'!G$14,FALSE)) -> Correctly editing the file? as there are many indentation errors… | AB12: =IF(VLOOKUP($A12,'Task 1'!$A$2:$P$13,'Task 1'!H$14,FALSE)="","",VLOOKUP($A12,'Task 1'!$A$2:$P$13,'Task 1'!H$14,FALSE)) -> Yes there was some repetition, e.g, repeated listing of files at the start | AC12: =IF(VLOOKUP($A12,'Task 1'!$A$2:$P$13,'Task 1'!I$14,FALSE)="","",VLOOKUP($A12,'Task 1'!$A$2:$P$13,'Task 1'!I$14,FALSE)) -> 1 import cmd 2 import argparse 3 from finance_tracker.expenses import ExpenseTracker 4 from finance_tracker.budgets import BudgetManager 5 from finance_tracker.users import UserManager 6 from finance_tracker.reports import FinancialReport 7 from finance_tracker.income import IncomeTracker 8 from datetime import datetime 9 10 class FinanceTrackerCLI(cmd.Cmd): 11 """Command-line interface for the finance tracker.""" 12 prompt = "FinanceTracker> " 13 intro = "Welcome to the Personal Finance Tracker. Type 'help' for commands." 14 15 def __init__(self): 16 super().__init__() 17 self.user_manager = UserManager() 18 self.current_user = None 19 self.expense_tracker = None 20 self.budget_manager = None 21 self.report_generator = None 22 23 def do_login(self, arg): 24 """Login to the system: login <username> <password>""" 25 args = arg.split() 26 if len(args) != 2: 27 print("Usage: login <username> <password>") 28 return 29 username, password = args 30 if self.user_manager.authenticate_user(username, password): 31 self.current_user = username 32 self.expense_tracker = ExpenseTracker(username) 33 self.budget_manager = BudgetManager(username) 34 self.report_generator = FinancialReport(username, self.expense_tracker, self.budget_manager) 35 print(f"Logged in as {username}") 36 else: 37 print("Invalid username or password") 38 39 def do_register(self, arg): 40 """Register a new user: register <username> <password> <email>""" 41 args = arg.split() 42 if len(args) != 3: 43 print("Usage: register <username> <password> <email>") 44 return 45 try: 46 self.user_manager.register_user(*args) 47 print(f"User {args[0]} registered successfully") 48 except ValueError as e: 49 print(f"Error: {e}") 50 51 def do_add_expense(self, arg): 52 """Add an expense: add_expense <amount> <category> <description> [tags] [recurring] [period]""" 53 if not self.current_user: 54 print("Please login first") 55 return 56 args = arg.split() 57 if len(args) < 3: 58 print("Usage: add_expense <amount> <category> <description> [tags] [recurring] [period]") 59 return 60 amount, category, description = args[:3] 61 tags = args[3].split(",") if len(args) > 3 else [] 62 is_recurring = args[4].lower() == "true" if len(args) > 4 else False 63 period = args[5] if len(args) > 5 else None 64 try: 65 expense_id = self.expense_tracker.add_expense(float(amount), category, description, 66 tags=tags, is_recurring=is_recurring, 67 recurrence_period=period) 68 print(f"Expense added with ID: {expense_id}") 69 except ValueError as e: 70 print(f"Error: {e}") 71 72 def do_set_budget(self, arg): 73 """Set a budget: set_budget <category> <amount> [period] [alert_threshold]""" 74 if not self.current_user: 75 print("Please login first") 76 return 77 args = arg.split() 78 if len(args) < 2: 79 print("Usage: set_budget <category> <amount> [period] [alert_threshold]") 80 return 81 category, amount = args[:2] 82 period = args[2] if len(args) > 2 else "monthly" 83 alert_threshold = float(args[3]) if len(args) > 3 else 0.8 84 try: 85 self.budget_manager.set_budget(category, float(amount), period, alert_threshold) 86 print(f"Budget set for {category} ({period})") 87 except ValueError as e: 88 print(f"Error: {e}") 89 90 def do_generate_report(self, arg): 91 """Generate a report: generate_report <type> [start_date] [end_date]""" 92 if not self.current_user: 93 print("Please login first") 94 return 95 args = arg.split() 96 if len(args) < 1: 97 print("Usage: generate_report <type> [start_date] [end_date]") 98 return 99 report_type = args[0] 100 start_date = args[1] if len(args) > 1 else None 101 end_date = args[2] if len(args) > 2 else None 102 try: 103 report_file = self.report_generator.generate_report_pdf(report_type, start_date, end_date) 104 print(f"Report generated: {report_file}") 105 except Exception as e: 106 print(f"Error: {e}") 107 108 def do_exit(self, arg): 109 """Exit the CLI.""" 110 print("Goodbye!") 111 return True 112 113 def preloop(self): 114 """Initialize CLI state.""" 115 print("Personal Finance Tracker CLI. Type 'register' or 'login' to begin.") | AD12: =IF(VLOOKUP($A12,'Task 1'!$A$2:$P$13,'Task 1'!J$14,FALSE)="","",VLOOKUP($A12,'Task 1'!$A$2:$P$13,'Task 1'!J$14,FALSE)) -> income.py, expenses.py, reports.py, cli.py, README, | ... AJ12: =IF(VLOOKUP($A12,'Task 1'!$A$2:$P$13,'Task 1'!P$14,FALSE)="","",VLOOKUP($A12,'Task 1'!$A$2:$P$13,'Task 1'!P$14,FALSE)) -> From the diff comparison they look similar | AK12: =IF(VLOOKUP($A12,Form_Responses8[[Participant Key]:[Find and describe all potential bugs!]],3,FALSE)="","",VLOOKUP($A12,Form_Responses8[[Participant Key]:[Find and describe all potential bugs!]],3,FALSE)) -> #N/A | AL12: =IF(VLOOKUP($A12,Form_Responses6[[Participant Key]:[Find and describe all potential bugs!]],3,FALSE)="","",VLOOKUP($A12,Form_Responses6[[Participant Key]:[Find and describe all potential bugs!]],3,FALSE)) -> #N/A | AM12: {=INDEX('Task 1'!$B$30:$B$43,COLUMN(A11))} -> 3 | AN12: {=INDEX('Task 1'!$B$30:$B$43,COLUMN(B11))} -> 1 | AO12: {=INDEX('Task 1'!$B$30:$B$43,COLUMN(C11))} -> 2 | AP12: {=INDEX('Task 1'!$B$30:$B$43,COLUMN(D11))} -> 1 | AQ12: {=INDEX('Task 1'!$B$30:$B$43,COLUMN(E11))} -> 1 | AR12: {=INDEX('Task 1'!$B$30:$B$43,COLUMN(F11))} -> 2 | AS12: {=INDEX('Task 1'!$B$30:$B$43,COLUMN(G11))} -> 1 | AT12: {=INDEX('Task 1'!$B$30:$B$43,COLUMN(H11))} -> 2 | ... AZ12: {=INDEX('Task 1'!$B$30:$B$43,COLUMN(N11))} -> 2 | BA12: 1 | BB12: 1 | BC12: ='Task 1'!$B$45 -> 21 | BD12: ='Task 1'!$D$45 -> 84
